OGR data source with driver: ESRI Shapefile 
Source: "/home/travis/github/cstdata/data/shapefiles/nps_boundary.shp", layer: "nps_boundary"
with 420 features
It has 11 fields
  |                                                                              |                                                                      |   0%Error in setTxtProgressBar(pb, i) : object 'i' not found
Calls: getParkpy -> system.time -> setTxtProgressBar -> <Anonymous>
Timing stopped at: 3.169 1.106 83.09
Execution halted
OGR data source with driver: ESRI Shapefile 
Source: "/home/travis/github/cstdata/data/shapefiles/nps_boundary.shp", layer: "nps_boundary"
with 420 features
It has 11 fields
HDF5-DIAG: Error detected in HDF5 (1.10.4) thread 140019278071744:
  #000: H5F.c line 444 in H5Fcreate(): unable to create file
    major: File accessibilty
    minor: Unable to open file
  #001: H5Fint.c line 1364 in H5F__create(): unable to open file
    major: File accessibilty
    minor: Unable to open file
  #002: H5Fint.c line 1615 in H5F_open(): unable to lock the file
    major: File accessibilty
    minor: Unable to open file
  #003: H5FD.c line 1640 in H5FD_lock(): driver lock request failed
    major: Virtual File Layer
    minor: Can't update object
  #004: H5FDsec2.c line 941 in H5FD_sec2_lock(): unable to lock file, errno = 11, error message = 'Resource temporarily unavailable'
    major: File accessibilty
    minor: Bad file ID accessed
Error in py_call_impl(callable, dots$args, dots$keywords) : 
  PermissionError: [Errno 13] Permission denied: b'/home/travis/github/cstdata/data/netcdfs/yellowstone_national_park/agg_macav2metdata_tasmin_bcc-csm1-1_r1i1p1_rcp45.nc'

Detailed traceback: 
  File "/home/travis/anaconda3/envs/dict/lib/python3.7/site-packages/xarray/core/dataset.py", line 1232, in to_netcdf
    compute=compute)
  File "/home/travis/anaconda3/envs/dict/lib/python3.7/site-packages/xarray/backends/api.py", line 734, in to_netcdf
    store = store_open(target, mode, format, group, **kwargs)
  File "/home/travis/anaconda3/envs/dict/lib/python3.7/site-packages/xarray/backends/netCDF4_.py", line 355, in open
    return cls(manager, lock=lock, autoclose=autoclose)
  File "/home/travis/anaconda3/envs/dict/lib/python3.7/site-packages/xarray/backends/netCDF4_.py", line 314, in __init__
    self.format = self.ds.data_model
  File "/home/travis/anaconda3/envs/dict/lib/python3.7/site-packages/xarray/backends/netCDF4_.py", line 359, in ds
    return self._manager.acquire().
Calls: getParkpy -> system.time -> <Anonymous> -> py_call_impl
Timing stopped at: 0.299 0.035 1.164
Execution halted
